<?xml version="1.0" encoding="UTF-8"?>
<sdf version='1.9'>
  <model name='t18_base'>
    <pose>0 0 0 0 0 0</pose>
    <self_collide>false</self_collide>
    <static>false</static>
    <link name="base_link">
      <inertial>
        <mass>11.5</mass>
        <inertia>
          <ixx>1.045</ixx>
          <ixy>0</ixy>
          <ixz>0</ixz>
          <iyy>1.608</iyy>
          <iyz>0</iyz>
          <izz>0.965</izz>
        </inertia>
      </inertial>
      <gravity>true</gravity>
      <velocity_decay/>
      <visual name="base_link_visual">
        <pose>0 0 0 0 0 0</pose>
        <geometry>
          <mesh>
            <scale>1 1 1</scale>
            <uri>model://t18_base/meshes/t18_model.dae</uri>
          </mesh>
        </geometry>
      </visual>
      <visual name="5010_motor_base_0">
        <pose>0.59 -0.245 0.46 0 0 0</pose>
        <geometry>
          <mesh>
            <scale>1 1 1</scale>
            <uri>model://t18_base/meshes/5010Base.dae</uri>
          </mesh>
        </geometry>
      </visual>
      <visual name="5010_motor_base_1">
        <pose>-0.59 0.245 0.46 0 0 0</pose>
        <geometry>
          <mesh>
            <scale>1 1 1</scale>
            <uri>model://t18_base/meshes/5010Base.dae</uri>
          </mesh>
        </geometry>
      </visual>
      <visual name="5010_motor_base_2">
        <pose>0.245 -0.59 0.46 0 0 0</pose>
        <geometry>
          <mesh>
            <scale>1 1 1</scale>
            <uri>model://t18_base/meshes/5010Base.dae</uri>
          </mesh>
        </geometry>
      </visual>
      <visual name="5010_motor_base_3">
        <pose>-0.59 -0.245 0.46 0 0 0</pose>
        <geometry>
          <mesh>
            <scale>1 1 1</scale>
            <uri>model://t18_base/meshes/5010Base.dae</uri>
          </mesh>
        </geometry>
      </visual>
      <visual name="5010_motor_base_4">
        <pose>0.59 0.245 0.46 0 0 0</pose>
        <geometry>
          <mesh>
            <scale>1 1 1</scale>
            <uri>model://t18_base/meshes/5010Base.dae</uri>
          </mesh>
        </geometry>
      </visual>
      <visual name="5010_motor_base_5">
        <pose>-0.245 0.59 0.46 0 0 0</pose>
        <geometry>
          <mesh>
            <scale>1 1 1</scale>
            <uri>model://t18_base/meshes/5010Base.dae</uri>
          </mesh>
        </geometry>
      </visual>
      <visual name="5010_motor_base_6">
        <pose>0.245 0.59 0.46 0 0 0</pose>
        <geometry>
          <mesh>
            <scale>1 1 1</scale>
            <uri>model://t18_base/meshes/5010Base.dae</uri>
          </mesh>
        </geometry>
      </visual>
      <visual name="5010_motor_base_7">
        <pose>-0.245 -0.59 0.46 0 0 0</pose>
        <geometry>
          <mesh>
            <scale>1 1 1</scale>
            <uri>model://t18_base/meshes/5010Base.dae</uri>
          </mesh>
        </geometry>
      </visual>
      <collision name="base_link_collision_0">
        <pose>0 0 .007 0 0 0</pose>
        <geometry>
          <box>
            <size>1.2 1.2 0.08</size>
          </box>
        </geometry>
        <surface>
          <contact>
            <ode>
              <min_depth>0.001</min_depth>
              <max_vel>0</max_vel>
            </ode>
          </contact>
          <friction>
            <ode/>
          </friction>
        </surface>
      </collision>
      <collision name="base_link_collision_1">
        <pose>0 -0.25 -.25 -0.35 0 0</pose>
        <geometry>
          <box>
            <size>0.02 0.02 0.35</size>
          </box>
        </geometry>
        <surface>
          <contact>
            <ode>
              <min_depth>0.001</min_depth>
              <max_vel>0</max_vel>
            </ode>
          </contact>
          <friction>
            <ode/>
          </friction>
        </surface>
      </collision>
      <collision name="base_link_collision_2">
        <pose>0 0.25 -.25 0.35 0 0</pose>
        <geometry>
          <box>
            <size>0.02 0.02 0.35</size>
          </box>
        </geometry>
        <surface>
          <contact>
            <ode>
              <min_depth>0.001</min_depth>
              <max_vel>0</max_vel>
            </ode>
          </contact>
          <friction>
            <ode/>
          </friction>
        </surface>
      </collision>
      <collision name="base_link_collision_3">
        <pose>-0.25 0 -.25 0 -0.35 0</pose>
        <geometry>
          <box>
            <size>0.02 0.02 0.35</size>
          </box>
        </geometry>
        <surface>
          <contact>
            <ode>
              <min_depth>0.001</min_depth>
              <max_vel>0</max_vel>
            </ode>
          </contact>
          <friction>
            <ode/>
          </friction>
        </surface>
      </collision>
      <collision name="base_link_collision_4">
        <pose>0.25 0 -.25 0 0.35 0</pose>
        <geometry>
          <box>
            <size>0.02 0.02 0.35</size>
          </box>
        </geometry>
        <surface>
          <contact>
            <ode>
              <min_depth>0.001</min_depth>
              <max_vel>0</max_vel>
            </ode>
          </contact>
          <friction>
            <ode/>
          </friction>
        </surface>
      </collision>
      <sensor name="air_pressure_sensor" type="air_pressure">
        <always_on>1</always_on>
        <update_rate>50</update_rate>
        <air_pressure>
          <pressure>
            <noise type="gaussian">
              <mean>0</mean>
              <stddev>0.01</stddev>
            </noise>
          </pressure>
        </air_pressure>
      </sensor>
      <sensor name="imu_sensor" type="imu">
        <always_on>1</always_on>
        <update_rate>250</update_rate>
        <imu>
          <angular_velocity>
            <x>
              <noise type="gaussian">
                <mean>0</mean>
                <stddev>0.00018665</stddev>
                <dynamic_bias_stddev>3.8785e-05</dynamic_bias_stddev>
                <dynamic_bias_correlation_time>1000</dynamic_bias_correlation_time>
              </noise>
            </x>
            <y>
              <noise type="gaussian">
                <mean>0</mean>
                <stddev>0.00018665</stddev>
                <dynamic_bias_stddev>3.8785e-05</dynamic_bias_stddev>
                <dynamic_bias_correlation_time>1000</dynamic_bias_correlation_time>
              </noise>
            </y>
            <z>
              <noise type="gaussian">
                <mean>0</mean>
                <stddev>0.00018665</stddev>
                <dynamic_bias_stddev>3.8785e-05</dynamic_bias_stddev>
                <dynamic_bias_correlation_time>1000</dynamic_bias_correlation_time>
              </noise>
            </z>
          </angular_velocity>
          <linear_acceleration>
            <x>
              <noise type="gaussian">
                <mean>0</mean>
                <stddev>0.00186</stddev>
                <dynamic_bias_stddev>0.006</dynamic_bias_stddev>
                <dynamic_bias_correlation_time>300</dynamic_bias_correlation_time>
              </noise>
            </x>
            <y>
              <noise type="gaussian">
                <mean>0</mean>
                <stddev>0.00186</stddev>
                <dynamic_bias_stddev>0.006</dynamic_bias_stddev>
                <dynamic_bias_correlation_time>300</dynamic_bias_correlation_time>
              </noise>
            </y>
            <z>
              <noise type="gaussian">
                <mean>0</mean>
                <stddev>0.00186</stddev>
                <dynamic_bias_stddev>0.006</dynamic_bias_stddev>
                <dynamic_bias_correlation_time>300</dynamic_bias_correlation_time>
              </noise>
            </z>
          </linear_acceleration>
        </imu>
      </sensor>
      <sensor name="navsat_sensor" type="navsat">
        <always_on>1</always_on>
        <update_rate>30</update_rate>
      </sensor>
    </link>
    <link name="rotor_0">
      <gravity>true</gravity>
      <self_collide>false</self_collide>
      <velocity_decay/>
      <pose>0.59 -0.245 0.488 0 0 0</pose>
      <inertial>
          <mass>0.279</mass>
          <inertia>
            <ixx>0.0048</ixx>
            <iyy>0.0048</iyy>
            <izz>0.0073</izz>
          </inertia>
        </inertial>
      <visual name="rotor_0_visual">
        <pose>0 0 -0.016 0 0 0</pose>
        <geometry>
          <mesh>
            <scale>1 1 1</scale>
            <uri>model://t18_base/meshes/1861_prop_cw.stl</uri>
          </mesh>
        </geometry>
        <material>
          <script>
            <name>Gazebo/DarkGrey</name>
            <uri>file://media/materials/scripts/gazebo.material</uri>
          </script>
        </material>
      </visual>
      <visual name="rotor_0_visual_motor_bell">
        <pose>0 0 -0.032 0 0 0</pose>
        <geometry>
          <mesh>
            <scale>1 1 1</scale>
            <uri>model://t18_base/meshes/5010Bell.dae</uri>
          </mesh>
        </geometry>
      </visual>
      <collision name="rotor_0_collision">
        <pose>0 0 0 0 0 0 </pose>
        <geometry>
          <cylinder>
            <radius>0.23</radius>
            <length>0.005</length>
          </cylinder>
        </geometry>
        <surface>
          <contact>
            <ode>
              <min_depth>0.001</min_depth>
              <max_vel>0</max_vel>
            </ode>
          </contact>
          <friction>
            <ode/>
          </friction>
        </surface>
      </collision>
    </link>
    <joint name="rotor_0_joint" type="revolute">
      <parent>base_link</parent>
      <child>rotor_0</child>
      <axis>
        <xyz>0 0 1</xyz>
        <limit>
          <lower>-1e+16</lower>
          <upper>1e+16</upper>
        </limit>
        <dynamics>
          <spring_reference>0</spring_reference>
          <spring_stiffness>0</spring_stiffness>
        </dynamics>
      </axis>
    </joint>
    <link name="rotor_1">
      <gravity>true</gravity>
      <self_collide>false</self_collide>
      <velocity_decay/>
      <pose>-0.59 0.245 0.488 0 0 0</pose>
      <inertial>
          <mass>0.279</mass>
          <inertia>
            <ixx>0.0048</ixx>
            <iyy>0.0048</iyy>
            <izz>0.0073</izz>
          </inertia>
        </inertial>
      <visual name="rotor_1_visual">
        <pose>0 0 -0.016 0 0 0</pose>
        <geometry>
          <mesh>
            <scale>1 1 1</scale>
            <uri>model://t18_base/meshes/1861_prop_cw.stl</uri>
          </mesh>
        </geometry>
        <material>
          <script>
            <name>Gazebo/DarkGrey</name>
            <uri>file://media/materials/scripts/gazebo.material</uri>
          </script>
        </material>
      </visual>
      <visual name="rotor_1_visual_motor_bell">
        <pose>0 0 -0.032 0 0 0</pose>
        <geometry>
          <mesh>
            <scale>1 1 1</scale>
            <uri>model://t18_base/meshes/5010Bell.dae</uri>
          </mesh>
        </geometry>
      </visual>
      <collision name="rotor_1_collision">
        <pose>0 0 0 0 0 0 </pose>
        <geometry>
          <cylinder>
            <radius>0.23</radius>
            <length>0.005</length>
          </cylinder>
        </geometry>
        <surface>
          <contact>
            <ode>
              <min_depth>0.001</min_depth>
              <max_vel>0</max_vel>
            </ode>
          </contact>
          <friction>
            <ode/>
          </friction>
        </surface>
      </collision>
    </link>
    <joint name="rotor_1_joint" type="revolute">
      <parent>base_link</parent>
      <child>rotor_1</child>
      <axis>
        <xyz>0 0 1</xyz>
        <limit>
          <lower>-1e+16</lower>
          <upper>1e+16</upper>
        </limit>
        <dynamics>
          <spring_reference>0</spring_reference>
          <spring_stiffness>0</spring_stiffness>
        </dynamics>
      </axis>
    </joint>
    <link name="rotor_2">
      <gravity>true</gravity>
      <self_collide>false</self_collide>
      <velocity_decay/>
      <pose>0.245 -0.59 0.488 0 0 0</pose>
      <inertial>
          <mass>0.279</mass>
          <inertia>
            <ixx>0.0048</ixx>
            <iyy>0.0048</iyy>
            <izz>0.0073</izz>
          </inertia>
        </inertial>
      <visual name="rotor_2_visual">
        <pose>0 0 -0.016 0 0 0</pose>
        <geometry>
          <mesh>
            <scale>1 1 1</scale>
            <uri>model://t18_base/meshes/1861_prop_ccw.stl</uri>
          </mesh>
        </geometry>
        <material>
          <script>
            <name>Gazebo/DarkGrey</name>
            <uri>file://media/materials/scripts/gazebo.material</uri>
          </script>
        </material>
      </visual>
      <visual name="rotor_2_visual_motor_bell">
        <pose>0 0 -0.032 0 0 0</pose>
        <geometry>
          <mesh>
            <scale>1 1 1</scale>
            <uri>model://t18_base/meshes/5010Bell.dae</uri>
          </mesh>
        </geometry>
      </visual>
      <collision name="rotor_2_collision">
        <pose>0 0 0 0 0 0 </pose>
        <geometry>
          <cylinder>
            <radius>0.23</radius>
            <length>0.005</length>
          </cylinder>
        </geometry>
        <surface>
          <contact>
            <ode>
              <min_depth>0.001</min_depth>
              <max_vel>0</max_vel>
            </ode>
          </contact>
          <friction>
            <ode/>
          </friction>
        </surface>
      </collision>
    </link>
    <joint name="rotor_2_joint" type="revolute">
      <parent>base_link</parent>
      <child>rotor_2</child>
      <axis>
        <xyz>0 0 1</xyz>
        <limit>
          <lower>-1e+16</lower>
          <upper>1e+16</upper>
        </limit>
        <dynamics>
          <spring_reference>0</spring_reference>
          <spring_stiffness>0</spring_stiffness>
        </dynamics>
      </axis>
    </joint>
    <link name="rotor_3">
      <gravity>true</gravity>
      <self_collide>false</self_collide>
      <velocity_decay/>
      <pose>-0.59 -0.245 0.488 0 0 0</pose>
      <inertial>
          <mass>0.279</mass>
          <inertia>
            <ixx>0.0048</ixx>
            <iyy>0.0048</iyy>
            <izz>0.0073</izz>
          </inertia>
        </inertial>
      <visual name="rotor_3_visual">
        <pose>0 0 -0.016 0 0 0</pose>
        <geometry>
          <mesh>
            <scale>1 1 1</scale>
            <uri>model://t18_base/meshes/1861_prop_ccw.stl</uri>
          </mesh>
        </geometry>
        <material>
          <script>
            <name>Gazebo/DarkGrey</name>
            <uri>file://media/materials/scripts/gazebo.material</uri>
          </script>
        </material>
      </visual>
      <visual name="rotor_3_visual_motor_bell">
        <pose>0 0 -0.032 0 0 0</pose>
        <geometry>
          <mesh>
            <scale>1 1 1</scale>
            <uri>model://t18_base/meshes/5010Bell.dae</uri>
          </mesh>
        </geometry>
      </visual>
      <collision name="rotor_3_collision">
        <pose>0 0 0 0 0 0 </pose>
        <geometry>
          <cylinder>
            <radius>0.23</radius>
            <length>0.005</length>
          </cylinder>
        </geometry>
        <surface>
          <contact>
            <ode>
              <min_depth>0.001</min_depth>
              <max_vel>0</max_vel>
            </ode>
          </contact>
          <friction>
            <ode/>
          </friction>
        </surface>
      </collision>
    </link>
    <joint name="rotor_3_joint" type="revolute">
      <parent>base_link</parent>
      <child>rotor_3</child>
      <axis>
        <xyz>0 0 1</xyz>
        <limit>
          <lower>-1e+16</lower>
          <upper>1e+16</upper>
        </limit>
        <dynamics>
          <spring_reference>0</spring_reference>
          <spring_stiffness>0</spring_stiffness>
        </dynamics>
      </axis>
    </joint>
    <link name="rotor_4">
      <gravity>true</gravity>
      <self_collide>false</self_collide>
      <velocity_decay/>
      <pose>0.59 0.245 0.488 0 0 0</pose>
      <inertial>
          <mass>0.279</mass>
          <inertia>
            <ixx>0.0048</ixx>
            <iyy>0.0048</iyy>
            <izz>0.0073</izz>
          </inertia>
        </inertial>
      <visual name="rotor_4_visual">
        <pose>0 0 -0.016 0 0 0</pose>
        <geometry>
          <mesh>
            <scale>1 1 1</scale>
            <uri>model://t18_base/meshes/1861_prop_ccw.stl</uri>
          </mesh>
        </geometry>
        <material>
          <script>
            <name>Gazebo/DarkGrey</name>
            <uri>file://media/materials/scripts/gazebo.material</uri>
          </script>
        </material>
      </visual>
      <visual name="rotor_4_visual_motor_bell">
        <pose>0 0 -0.032 0 0 0</pose>
        <geometry>
          <mesh>
            <scale>1 1 1</scale>
            <uri>model://t18_base/meshes/5010Bell.dae</uri>
          </mesh>
        </geometry>
      </visual>
      <collision name="rotor_4_collision">
        <pose>0 0 0 0 0 0 </pose>
        <geometry>
          <cylinder>
            <radius>0.23</radius>
            <length>0.005</length>
          </cylinder>
        </geometry>
        <surface>
          <contact>
            <ode>
              <min_depth>0.001</min_depth>
              <max_vel>0</max_vel>
            </ode>
          </contact>
          <friction>
            <ode/>
          </friction>
        </surface>
      </collision>
    </link>
    <joint name="rotor_4_joint" type="revolute">
      <parent>base_link</parent>
      <child>rotor_4</child>
      <axis>
        <xyz>0 0 1</xyz>
        <limit>
          <lower>-1e+16</lower>
          <upper>1e+16</upper>
        </limit>
        <dynamics>
          <spring_reference>0</spring_reference>
          <spring_stiffness>0</spring_stiffness>
        </dynamics>
      </axis>
    </joint>
    <link name="rotor_5">
      <gravity>true</gravity>
      <self_collide>false</self_collide>
      <velocity_decay/>
      <pose>-0.245 0.59 0.488 0 0 0</pose>
      <inertial>
          <mass>0.279</mass>
          <inertia>
            <ixx>0.0048</ixx>
            <iyy>0.0048</iyy>
            <izz>0.0073</izz>
          </inertia>
        </inertial>
      <visual name="rotor_5_visual">
        <pose>0 0 -0.016 0 0 0</pose>
        <geometry>
          <mesh>
            <scale>1 1 1</scale>
            <uri>model://t18_base/meshes/1861_prop_ccw.stl</uri>
          </mesh>
        </geometry>
        <material>
          <script>
            <name>Gazebo/DarkGrey</name>
            <uri>file://media/materials/scripts/gazebo.material</uri>
          </script>
        </material>
      </visual>
      <visual name="rotor_5_visual_motor_bell">
        <pose>0 0 -0.032 0 0 0</pose>
        <geometry>
          <mesh>
            <scale>1 1 1</scale>
            <uri>model://t18_base/meshes/5010Bell.dae</uri>
          </mesh>
        </geometry>
      </visual>
      <collision name="rotor_5_collision">
        <pose>0 0 0 0 0 0 </pose>
        <geometry>
          <cylinder>
            <radius>0.23</radius>
            <length>0.005</length>
          </cylinder>
        </geometry>
        <surface>
          <contact>
            <ode>
              <min_depth>0.001</min_depth>
              <max_vel>0</max_vel>
            </ode>
          </contact>
          <friction>
            <ode/>
          </friction>
        </surface>
      </collision>
    </link>
    <joint name="rotor_5_joint" type="revolute">
      <parent>base_link</parent>
      <child>rotor_5</child>
      <axis>
        <xyz>0 0 1</xyz>
        <limit>
          <lower>-1e+16</lower>
          <upper>1e+16</upper>
        </limit>
        <dynamics>
          <spring_reference>0</spring_reference>
          <spring_stiffness>0</spring_stiffness>
        </dynamics>
      </axis>
    </joint>
   <link name="rotor_6">
      <gravity>true</gravity>
      <self_collide>false</self_collide>
      <velocity_decay/>
      <pose>0.245 0.59 0.488 0 0 0</pose>
      <inertial>
          <mass>0.279</mass>
          <inertia>
            <ixx>0.0048</ixx>
            <iyy>0.0048</iyy>
            <izz>0.0073</izz>
          </inertia>
        </inertial>
      <visual name="rotor_6_visual">
        <pose>0 0 -0.016 0 0 0</pose>
        <geometry>
          <mesh>
            <scale>1 1 1</scale>
            <uri>model://t18_base/meshes/1861_prop_cw.stl</uri>
          </mesh>
        </geometry>
        <material>
          <script>
            <name>Gazebo/DarkGrey</name>
            <uri>file://media/materials/scripts/gazebo.material</uri>
          </script>
        </material>
      </visual>
      <visual name="rotor_6_visual_motor_bell">
        <pose>0 0 -0.032 0 0 0</pose>
        <geometry>
          <mesh>
            <scale>1 1 1</scale>
            <uri>model://t18_base/meshes/5010Bell.dae</uri>
          </mesh>
        </geometry>
      </visual>
      <collision name="rotor_6_collision">
        <pose>0 0 0 0 0 0 </pose>
        <geometry>
          <cylinder>
            <radius>0.23</radius>
            <length>0.005</length>
          </cylinder>
        </geometry>
        <surface>
          <contact>
            <ode>
              <min_depth>0.001</min_depth>
              <max_vel>0</max_vel>
            </ode>
          </contact>
          <friction>
            <ode/>
          </friction>
        </surface>
      </collision>
    </link>
    <joint name="rotor_6_joint" type="revolute">
      <parent>base_link</parent>
      <child>rotor_6</child>
      <axis>
        <xyz>0 0 1</xyz>
        <limit>
          <lower>-1e+16</lower>
          <upper>1e+16</upper>
        </limit>
        <dynamics>
          <spring_reference>0</spring_reference>
          <spring_stiffness>0</spring_stiffness>
        </dynamics>
      </axis>
    </joint>
    <link name="rotor_7">
      <gravity>true</gravity>
      <self_collide>false</self_collide>
      <velocity_decay/>
      <pose>-0.245 -0.59 0.488 0 0 0</pose>
      <inertial>
          <mass>0.279</mass>
          <inertia>
            <ixx>0.0048</ixx>
            <iyy>0.0048</iyy>
            <izz>0.0073</izz>
          </inertia>
        </inertial>
      <visual name="rotor_7_visual">
        <pose>0 0 -0.016 0 0 0</pose>
        <geometry>
          <mesh>
            <scale>1 1 1</scale>
            <uri>model://t18_base/meshes/1861_prop_cw.stl</uri>
          </mesh>
        </geometry>
        <material>
          <script>
            <name>Gazebo/DarkGrey</name>
            <uri>file://media/materials/scripts/gazebo.material</uri>
          </script>
        </material>
      </visual>
      <visual name="rotor_7_visual_motor_bell">
        <pose>0 0 -0.032 0 0 0</pose>
        <geometry>
          <mesh>
            <scale>1 1 1</scale>
            <uri>model://t18_base/meshes/5010Bell.dae</uri>
          </mesh>
        </geometry>
      </visual>
      <collision name="rotor_7_collision">
        <pose>0 0 0 0 0 0 </pose>
        <geometry>
          <cylinder>
            <radius>0.23</radius>
            <length>0.005</length>
          </cylinder>
        </geometry>
        <surface>
          <contact>
            <ode>
              <min_depth>0.001</min_depth>
              <max_vel>0</max_vel>
            </ode>
          </contact>
          <friction>
            <ode/>
          </friction>
        </surface>
      </collision>
    </link>
    <joint name="rotor_7_joint" type="revolute">
      <parent>base_link</parent>
      <child>rotor_7</child>
      <axis>
        <xyz>0 0 1</xyz>
        <limit>
          <lower>-1e+16</lower>
          <upper>1e+16</upper>
        </limit>
        <dynamics>
          <spring_reference>0</spring_reference>
          <spring_stiffness>0</spring_stiffness>
        </dynamics>
      </axis>
    </joint>
  </model>
</sdf>
